tests/complex/complex_0.in
40
o
23 S 100 BKD 235 93
29 S 101 AWP 1352 330
15 B 102 ACP 251 415
30 B 103 ATH^D 910 28
10 B 104 AAN 1759 82
5 B 105 ALG 872 450
12 S 106 ASAI 498 464
32 S 107 BDXB 1967 29
4 S 108 ASPN 1274 612
9 B 109 AQNA 117 763
0 B 110 AFGD 1119 36
29 S 111 ASAI 666 98
34 B 112 BAC^E 924 598
5 B 113 AGM^D 1464 588
12 B 114 AMG 1794 714
29 B 115 BAC 1405 517
2 B 116 BIP^A 1604 317
36 B 117 BILL 861 648
0 B 118 ASA 1130 861
17 S 119 ASB 1098 771
29 B 120 BBY 1872 182
8 S 121 ARGO 1520 180
15 B 122 AMBC 1419 530
35 B 123 ATH^E 1262 590
33 B 124 ASAI 657 846
7 B 125 AEVA 1233 928
9 B 126 AFT 1339 661
34 S 127 BK 670 792
10 B 128 AGM^D 1961 503
26 S 129 BBDC 1554 441
2 S 130 BAC^L 514 874
34 S 131 AMK 1479 669
26 S 132 AHL^C 1354 622
5 B 133 AEL^A 278 973
36 S 134 ACN 572 305
34 B 135 ATCO^I 883 182
18 S 136 ACDI 260 618
3 B 137 BFZ 1438 426
20 B 138 BMI 157 985
16 S 139 ADX 919 826
20 S 140 BAC^M 1921 771
14 B 141 ALCC 935 857
39 S 142 AVNT 218 773
12 B 143 BGX 1181 698
35 B 144 ATCO^D 104 153
37 S 145 AHT^H 1321 373
25 S 146 AL^A 1494 978
21 B 147 BAC^Q 293 702
31 B 148 BBW 683 419
13 B 149 BAX 1064 402
39 S 150 AON 534 792
30 S 151 AIRC 1507 366
38 S 152 AROC 993 869
12 B 153 BIP 1585 13
28 B 154 AGM^D 1698 383
16 S 155 ABC 716 660
39 B 156 ANET 797 869
37 B 157 AAN 943 316
7 S 158 BEST 133 42
8 S 159 ABG 637 735
16 S 160 ASC 532 987
24 S 161 AC 1257 424
11 S 162 ATCO^I 676 932
7 S 163 BKE 151 51
1 B 164 AAIC^C 764 705
18 B 165 AGAC 333 286
36 B 166 AWI 974 646
15 B 167 AI 244 392
15 S 168 ARW 1261 534
2 S 169 AP 1060 171
30 B 170 AMK 253 288
8 B 171 AVD 1660 919
7 S 172 BCC 1001 406
6 S 173 ATH^A 1401 151
15 S 174 BKN 1312 755
38 B 175 AME 514 854
27 S 176 BBLN 1533 545
39 B 177 ADNT 1536 83
3 S 178 AMCR 1836 421
6 S 179 BEST 1334 456
22 B 180 BC^B 1588 598
6 B 181 ACR 1017 862
26 S 182 AVTR 1486 495
12 B 183 ARR 510 177
10 S 184 ACDI 1762 334
9 B 185 AMPY 1025 358
1 B 186 ALLY 1024 395
8 S 187 BEPI 528 216
22 B 188 APLE 878 394
13 B 189 AIRC 374 449
27 B 190 BABA 1033 226
30 B 191 BAP 476 710
0 S 192 AJX 551 853
5 S 193 AFGC 772 709
18 B 194 AGTI 309 29
29 B 195 BAC^P 692 535
10 B 196 AROC 491 541
13 B 197 ATH^D 425 909
36 B 198 BDC 592 756
39 S 199 BIO/B 994 78
16 S 200 ATUS 1654 446
4 B 201 AGL 1769 757
2 B 202 ALL^B 1537 226
10 S 203 AFTR 1823 67
25 B 204 BCO 278 479
37 B 205 AMP 1995 720
3 S 206 AP 1121 114
23 B 207 BLW 1929 506
16 B 208 AHT^F 1883 847
28 S 209 AOS 443 174
7 S 210 BMI 480 630
27 B 211 ACA 854 502
18 B 212 AMPX 1864 365
20 B 213 ANF 1067 86
1 S 214 ATI 1984 935
37 S 215 BKKT 451 243
11 S 216 AEO 1518 437
23 B 217 AHT^F 509 148
1 S 218 AFGD 1629 447
38 S 219 ALL 1283 587
34 B 220 BLK 896 294
10 S 221 AHH 614 873
6 B 222 ATO 1904 132
38 B 223 AVY 1341 846
8 S 224 AZUL 511 361
0 S 225 ALL^B 217 524
24 S 226 AAIC 1083 756
34 B 227 ABR^E 948 269
11 B 228 ASB 1572 160
6 B 229 APTV 778 909
4 S 230 BLE 573 441
22 S 231 BACA 511 899
24 S 232 A 1823 311
23 B 233 ACDI 1683 302
34 S 234 AQUA 1023 390
33 S 235 AROC 395 679
16 S 236 AHH 656 678
2 B 237 BMAC 177 894
9 S 238 ADC^A 1213 335
31 B 239 ALE 1936 278
14 B 240 ALL 1307 895
38 B 241 BAC 128 738
34 S 242 ACR^C 1759 295
37 S 243 ARL 553 483
31 S 244 ARLO 1003 698
21 B 245 AAIC 1692 101
34 B 246 AMH^G 1027 364
31 S 247 AKO/B 1790 165
31 B 248 BGY 1220 328
35 S 249 ABG 1577 648
22 S 250 AHL^D 107 638
2 S 251 APO 1766 804
16 S 252 BBW 1240 757
28 S 253 BGSF 816 272
17 B 254 AIR 640 502
25 B 255 AVD 1795 81
33 B 256 BFAM 636 808
22 B 257 BBDC 424 528
11 S 258 AGM^D 1689 530
12 S 259 AGTI 1992 416
36 B 260 AVA 521 132
17 B 261 AYI 1835 429
17 S 262 AP 1886 47
34 B 263 ALLG 1978 816
7 B 264 AMH 1369 774
18 B 265 ALTG^A 450 70
13 B 266 ALLE 1523 971
21 B 267 BGR 1115 148
26 B 268 AIT 1143 519
16 B 269 BIGZ 924 182
39 B 270 ACA 480 917
39 B 271 BLCO 1981 602
9 S 272 AP 191 861
29 S 273 AGM^C 138 737
7 S 274 AP 839 384
19 B 275 ACHR 1830 151
39 B 276 AEL 1072 713
19 B 277 AKR 108 670
19 S 278 BLD 1575 446
22 B 279 AL^A 506 610
6 B 280 ACRE 1596 660
30 S 281 BDC 707 858
36 S 282 AGI 1745 687
8 S 283 AXS^E 1864 600
32 B 284 BMI 835 836
34 B 285 AX 534 92
17 B 286 ATH^C 1070 318
37 B 287 BCX 1409 200
9 S 288 BHIL 409 994
17 S 289 AJG 556 286
21 B 290 BAC^O 761 832
11 B 291 APTV 1389 972
36 B 292 BKH 1935 49
9 B 293 ALE 1350 352
4 S 294 AKR 1035 361
38 S 295 ASB^E 1395 207
11 S 296 BFAC 280 647
38 S 297 AMK 233 763
1 B 298 AXL 1415 997
4 S 299 ATH^E 299 544
6 B 300 BBD 1602 119
26 S 301 BBLN 989 845
35 S 302 ACR^D 1166 652
29 B 303 ATTO 1620 977
8 B 304 AENZ 1539 959
15 S 305 BEST 1894 591
30 S 306 BBY 723 856
13 S 307 ABG 995 491
7 S 308 AGX 1043 414
29 B 309 ARCH 1118 517
31 S 310 BF/A 1921 290
23 B 311 AAIN 1299 928
22 S 312 ADC^A 456 376
24 B 313 BIPH 300 806
4 S 314 BIP 588 682
9 B 315 AAM^A 699 319
6 B 316 AMH^H 1281 628
20 S 317 ADNT 1447 685
38 B 318 ASGN 767 20
8 S 319 BALL 725 38
19 B 320 AGTI 1098 904
16 S 321 ATCO 1719 321
26 B 322 AHL^C 1331 139
11 S 323 AC 742 780
11 B 324 AL 1525 604
26 B 325 BME 1006 510
38 B 326 BHG 1959 523
19 S 327 AHT^I 196 999
8 S 328 APG 1069 623
7 B 329 AZUL 1771 879
36 S 330 BGS 1676 483
11 B 331 BFAM 1652 824
25 S 332 AHT^D 295 479
38 B 333 ACP 1888 796
10 B 334 BGH 849 702
10 S 335 APD 299 299
38 B 336 ADX 683 862
25 B 337 ACM 1568 919
27 S 338 ALTG^A 1594 450
2 B 339 AVTR 1534 168
10 B 340 BG 1194 519
10 S 341 BB 1920 633
29 B 342 ANAC 1316 855
25 S 343 AGAC 1786 292
30 S 344 AKR 499 395
35 B 345 BC^C 239 431
5 S 346 BDJ 583 613
31 S 347 AOD 1343 538
29 S 348 AIC 180 786
1 S 349 ACDI 486 782
38 S 350 ARC 1499 601
23 S 351 AMBP 269 560
32 S 352 BHK 1365 347
6 B 353 AMK 1392 693
16 B 354 BHK 1128 60
15 S 355 BDX 1588 216
27 B 356 ACDI 1802 668
9 B 357 ACI 1124 865
21 S 358 AXP 487 151
32 S 359 AC 685 714
8 S 360 ARGO^A 751 590
18 B 361 ADNT 451 551
9 S 362 ADX 529 15
8 S 363 AJG 893 260
23 S 364 AAM^B 1454 585
10 S 365 BEPI 1678 66
36 S 366 ANAC 1725 835
15 S 367 BIP^A 142 71
10 B 368 ALLG 1154 556
6 S 369 ARDC 965 711
2 B 370 AKO/A 1728 194
33 B 371 BCO 119 723
3 S 372 ACA 1180 879
17 S 373 ACP^A 1187 994
20 S 374 ATI 578 431
36 S 375 BLW 1160 482
25 B 376 ALE 1068 421
20 S 377 ATUS 1819 709
19 B 378 AJRD 1090 990
9 B 379 ARGO 1826 104
29 B 380 APE 560 729
21 B 381 AMRX 209 317
7 S 382 BFS^D 797 456
24 S 383 ATCO^I 727 736
4 S 384 BIP^A 1614 93
29 B 385 BHIL 767 607
9 S 386 ASR 1393 968
37 S 387 ABR^F 1144 854
27 S 388 AMAM 185 704
36 B 389 ALK 716 551
29 S 390 AIRC 395 124
8 S 391 AJG 120 975
26 B 392 AMOV 1187 537
25 S 393 AIV 964 530
10 B 394 ATGE 1762 466
0 S 395 BKT 1313 571
11 B 396 BIPH 559 213
29 B 397 AMCR 1828 955
3 B 398 ABBV 1222 384
6 B 399 BLW 569 802
11 S 400 ARC 487 217
13 B 401 BEN 949 828
37 B 402 AUD 1976 372
15 B 403 AHT^G 1982 347
27 S 404 AFGE 620 780
37 S 405 BBVA 662 270
3 S 406 ASB 815 503
8 S 407 ASH 1704 295
24 B 408 BBAR 1624 631
2 S 409 AGM^C 1328 216
33 S 410 ALL^I 193 808
37 B 411 AGTI 542 14
16 B 412 BCH 731 81
8 S 413 BIG 1889 998
22 B 414 AGM^E 494 61
31 S 415 BKT 1581 331
24 B 416 BHVN 108 118
38 B 417 ABG 1720 634
20 B 418 ALL 934 931
39 S 419 ASB^F 1293 700
28 S 420 ATO 1583 964
27 S 421 BC^B 1573 677
35 S 422 ARLO 290 815
2 B 423 ASC 1278 853
29 S 424 ACR^D 1920 366
33 B 425 BHG 217 900
17 S 426 BC 1992 883
10 B 427 AJXA 291 414
9 S 428 AMRC 180 679
39 S 429 BK 1915 775
20 S 430 ARIS 141 954
1 B 431 AQNU 1632 601
11 B 432 AOS 1456 792
16 B 433 BF/B 469 489
16 B 434 AZO 1928 493
22 S 435 BFH 1668 681
0 S 436 AEO 1297 273
33 B 437 BHR^B 1139 476
19 B 438 APCA 916 503
2 S 439 AMCR 487 548
33 B 440 AVA 577 228
33 S 441 AOD 1711 851
16 B 442 ATI 1922 873
10 S 443 ARCH 1753 733
9 S 444 BLE 977 827
25 S 445 AM 1949 980
30 S 446 AMBC 456 284
31 B 447 BHIL 1820 418
35 B 448 BMI 1809 415
25 B 449 BHLB 1218 694
5 S 450 BHVN 668 288
30 B 451 AHT^G 169 823
17 S 452 AMPX 1680 513
3 S 453 BBLN 1620 430
9 B 454 BC^B 1411 513
37 S 455 BML^H 1204 546
16 S 456 BEPH 290 187
2 B 457 BMEZ 416 10
19 S 458 ALX 675 190
0 S 459 AYX 1836 181
17 S 460 BLE 1781 833
2 S 461 BBVA 682 171
31 S 462 ABR^E 784 927
12 B 463 BAC^O 423 316
17 S 464 BIPH 298 545
16 B 465 BHIL 115 710
