tests/complex/complex_1.in
40
o
15 B 100 BK 414 27
19 B 101 AGM^C 1914 339
7 S 102 AAN 873 307
12 S 103 BHVN 1672 852
39 B 104 AMTD 500 680
5 S 105 BFLY 1856 219
29 S 106 BKKT 551 701
33 B 107 BEN 1121 345
8 S 108 ATAQ 614 278
27 B 109 BAC 373 502
11 B 110 AHT^I 1726 166
16 B 111 BAC^P 245 199
5 S 112 AIT 161 179
2 S 113 BML^H 1644 984
0 S 114 AC 605 88
23 S 115 BBVA 1851 543
25 S 116 AOMR 308 761
8 B 117 AR 1779 756
38 S 118 BME 640 338
7 B 119 AHH 692 478
27 S 120 AAIC^C 1639 198
9 B 121 AMOV 1500 517
11 S 122 AGO 399 606
26 S 123 BDC 288 929
33 B 124 BALL 340 309
38 B 125 ACV 1224 219
33 S 126 BHK 937 213
2 S 127 BAC^O 1176 614
37 S 128 BAH 166 34
35 B 129 AGD 1791 67
22 B 130 ACR 1701 78
37 B 131 AMBP 977 736
4 B 132 AKA 1507 247
38 S 133 AAN 1359 652
39 B 134 ALL 1255 740
25 B 135 BLK 224 220
14 S 136 BG 845 721
30 S 137 AME 1112 567
33 B 138 ACCO 903 136
21 B 139 BIO 290 329
28 S 140 AVAL 1415 332
28 B 141 AAIN 686 435
17 S 142 BA 1340 777
29 S 143 AEL^B 897 171
22 B 144 AEO 674 40
20 B 145 ALB 1763 762
23 S 146 AXS^E 1866 781
10 B 147 BKKT 1720 799
17 S 148 AL^A 1793 547
28 B 149 ACA 1540 591
30 S 150 AENZ 613 907
21 B 151 BKKT 903 18
23 B 152 BDC 1324 225
31 B 153 BA 1478 654
35 B 154 AAN 1509 32
35 S 155 BFLY 494 404
28 B 156 ASB^E 925 18
30 S 157 BARK 184 808
33 B 158 APLE 126 430
10 B 159 BLE 622 811
20 B 160 ALEX 1736 819
13 S 161 AZO 870 462
31 B 162 AENZ 493 520
27 S 163 AL 968 768
35 S 164 AMRX 1863 521
1 S 165 BIP 1335 657
8 B 166 ARES 1917 763
9 S 167 AFGE 1798 599
17 B 168 BMEZ 1640 431
13 B 169 BMAC 665 440
36 S 170 ATH^C 939 594
29 B 171 AER 1944 14
24 B 172 ADT 1690 697
27 S 173 BBUC 406 688
4 S 174 ASAN 1242 345
34 B 175 ALIT 267 86
34 B 176 AEVA 1813 26
35 S 177 ASAN 1101 257
25 B 178 AMX 514 469
2 B 179 BG 116 430
19 B 180 BIGZ 1330 531
11 S 181 AFB 638 596
24 B 182 AOS 414 947
29 B 183 BKKT 1326 93
24 S 184 BKN 851 414
37 B 185 AWI 1673 411
1 B 186 BHC 1964 944
7 B 187 BAX 756 548
26 S 188 APAM 1895 81
35 S 189 ASC 739 274
11 S 190 AHL^C 151 140
11 B 191 AZUL 866 822
12 B 192 BCC 1531 164
20 S 193 AEM 1522 913
5 B 194 BHR 429 454
9 S 195 AKO/B 1026 921
37 B 196 AVAL 339 957
22 S 197 AHT^D 1635 191
21 S 198 ABT 1347 228
13 S 199 AVY 1094 869
33 B 200 ALLE 1777 326
27 B 201 BAC^L 760 16
34 S 202 ACP^A 807 566
30 B 203 BAC^P 145 260
16 B 204 APD 1689 450
6 B 205 AESC 565 95
22 S 206 BML^G 373 825
29 S 207 AEE 222 40
38 S 208 AHL^C 445 294
11 B 209 ALCC 1089 186
19 S 210 AIV 1644 481
37 S 211 BAC^K 1754 777
5 B 212 ATH^A 1255 284
2 S 213 ASGN 1019 580
37 S 214 BARK 155 441
35 B 215 BAK 440 296
24 B 216 AMT 1535 677
5 B 217 AMOV 1442 810
26 B 218 ACP 449 215
15 S 219 ALTG 646 296
25 S 220 AFB 1820 618
17 B 221 BMAC 598 901
14 S 222 AP 1187 518
36 B 223 BDN 805 189
38 S 224 ASIX 146 438
19 B 225 ADX 929 469
7 B 226 AWI 1623 677
5 B 227 BCAT 1345 331
34 S 228 AGAC 667 98
4 B 229 ALSN 1412 440
13 B 230 AAN 1723 904
17 S 231 BEPH 1914 971
35 B 232 AWP 1213 521
11 B 233 ALC 1870 835
32 S 234 AAT 1538 947
22 B 235 ATCO^H 1263 928
10 S 236 AIF 1323 270
27 B 237 ARCH 1954 919
13 B 238 BCS 1803 853
1 B 239 APCA 248 443
39 B 240 BAP 611 25
24 B 241 BABA 1437 505
11 S 242 AIRC 1318 104
19 B 243 AHL^E 1301 793
5 B 244 AIG 738 921
8 B 245 AMT 100 558
31 S 246 ALK 1703 545
23 B 247 ALL^I 1025 152
28 B 248 AMTD 1865 677
21 B 249 AWF 1308 415
27 S 250 AFGC 807 718
33 S 251 ARNC 1781 46
25 B 252 AXL 280 540
33 S 253 BIP^B 1467 252
2 B 254 AKO/A 502 206
20 S 255 AXP 783 450
38 S 256 BKT 1213 77
26 B 257 BAC^Q 416 742
19 B 258 AEM 618 494
36 S 259 ALL^B 1240 332
14 B 260 BBAI 500 291
13 B 261 ARCH 913 105
21 S 262 AHL^E 1224 35
11 B 263 BBW 1808 988
23 B 264 AER 1809 540
27 B 265 AJRD 485 376
34 B 266 BDJ 1949 63
3 B 267 ABEV 682 704
27 S 268 APD 866 738
28 S 269 BKE 1746 423
30 S 270 AKO/A 698 896
37 B 271 AMP 525 986
18 B 272 ATEK 702 879
38 B 273 BCAT 1094 79
9 S 274 APG 1482 109
30 B 275 AWR 289 54
4 B 276 AYX 990 770
10 B 277 AYI 1821 51
38 S 278 BCS 1108 843
20 S 279 ARES 352 624
35 B 280 AEM 1747 416
23 S 281 BHR 1281 690
28 B 282 AEO 1706 144
11 S 283 BAC^N 383 775
37 B 284 BIPC 1078 865
34 S 285 A 1073 252
25 S 286 APH 617 598
3 S 287 AXR 298 779
12 S 288 BLK 1766 87
38 S 289 AIV 1172 131
29 B 290 ATI 844 436
1 S 291 BML^H 1810 286
37 S 292 ATTO 1469 702
11 S 293 AGM^D 588 533
5 B 294 ABR^F 660 201
14 B 295 AQUA 1381 190
7 S 296 ARIS 930 101
37 S 297 BBDC 1219 886
15 B 298 ABEV 1374 823
14 B 299 AZEK 403 260
33 B 300 AHL^E 1742 98
7 S 301 AIN 1219 171
9 S 302 BHR^D 1762 738
32 B 303 BABA 1206 834
37 B 304 APRN 313 589
30 S 305 BEP^A 1580 584
26 B 306 AOMR 1655 155
38 S 307 AEL^A 1560 675
6 S 308 AOMR 477 248
15 B 309 AER 1117 372
25 B 310 BCX 836 240
25 B 311 BEST 1935 385
20 B 312 ARE 1827 292
34 B 313 AQNU 626 886
1 B 314 AHL^D 1442 200
7 S 315 BAC^O 1728 458
17 B 316 AMX 1701 373
4 B 317 BCAT 981 615
9 S 318 A 877 552
6 S 319 ABR 1039 193
22 B 320 BAH 1767 427
22 B 321 AMN 1538 335
10 S 322 BKI 113 924
35 S 323 BLD 1192 595
4 S 324 B 116 245
13 B 325 BKH 643 919
7 B 326 BHG 1499 941
16 S 327 BKT 1162 875
3 S 328 BIP 702 262
14 B 329 BGR 1506 484
14 B 330 BF/B 1002 32
7 B 331 AGX 1958 193
34 S 332 BABA 950 564
3 S 333 AGM 1670 420
38 S 334 AER 1794 470
14 S 335 AZUL 1867 251
4 B 336 ARMK 1206 227
34 B 337 ABB 750 758
10 S 338 ADC^A 431 384
20 B 339 ALLY 1404 160
13 S 340 BIO/B 267 235
5 S 341 ATH^B 1899 43
36 B 342 ASIX 1430 849
21 S 343 BIPH 1634 148
8 S 344 AMWL 927 471
11 B 345 ARGO^A 283 90
17 S 346 BAC^O 1162 391
16 S 347 A 380 485
34 B 348 BHC 1950 481
18 S 349 AAIC 163 358
5 B 350 ACRE 162 961
25 B 351 AYX 1326 882
27 S 352 ALC 858 662
38 S 353 ARGO 998 797
5 S 354 BML^H 1772 255
13 S 355 ARDC 1992 807
29 B 356 AMX 1934 746
2 B 357 AIU 916 705
29 B 358 BLCO 1365 636
0 B 359 AXS^E 768 758
32 B 360 BH 613 492
18 B 361 ATCO^I 1606 441
22 S 362 ACV 1081 727
23 S 363 AAP 298 72
18 S 364 APAM 1098 984
39 S 365 BAH 206 679
31 B 366 ATH^D 183 945
12 B 367 BAC 566 561
25 B 368 AMP 462 299
22 B 369 AMC 1577 903
3 B 370 BAC^K 670 964
28 S 371 ALEX 1273 843
24 B 372 ALL^H 1524 80
29 B 373 AVA 1106 562
14 B 374 AQNU 1014 378
26 S 375 AXP 1676 25
5 B 376 AHT^H 1852 185
7 B 377 AUB 701 851
24 B 378 AVTR 1397 36
25 S 379 BBD 1740 105
36 B 380 AMWL 1458 57
19 S 381 BBD 521 460
33 B 382 BBN 1414 173
33 S 383 BKDT 1853 236
21 S 384 ARCH 214 225
13 S 385 AGO 1965 741
20 S 386 BEPH 318 317
3 B 387 AU 1649 461
22 B 388 AG 1911 562
24 B 389 ANF 264 442
28 B 390 AFGD 1678 58
10 B 391 AWI 1005 791
21 S 392 AUB^A 1650 263
2 B 393 BAP 1507 575
34 B 394 ASR 1565 182
21 B 395 BIPC 984 433
17 B 396 AUB^A 1700 497
17 S 397 B 1546 57
3 B 398 APH 1111 597
36 S 399 APG 1607 175
19 S 400 AA 724 658
22 B 401 AAIN 147 342
25 B 402 AGM 1135 401
35 B 403 AZEK 1853 431
7 B 404 ADC 1085 363
10 B 405 ALK 321 917
23 B 406 BFS^D 780 355
18 B 407 APO 903 248
26 B 408 AMH^H 1312 445
30 B 409 ATH^B 1399 200
8 S 410 ALLG 334 323
33 S 411 AJG 286 407
39 B 412 ALL^G 499 784
2 S 413 BEN 909 599
16 B 414 AU 1163 96
30 S 415 ARGD 1714 269
37 B 416 AXR 1136 752
9 B 417 BMAC 958 837
22 B 418 AGR 463 735
33 B 419 BAC^M 615 337
11 S 420 AEO 1708 881
6 S 421 ATH^D 1365 720
34 B 422 AIU 1406 369
39 S 423 AMH^G 1663 207
31 S 424 BHC 112 260
7 S 425 BBDO 1419 192
32 B 426 BBD 1048 129
9 B 427 BBW 1035 837
12 B 428 AU 314 63
22 S 429 BLUA 611 179
28 B 430 ARR^C 970 77
3 S 431 ADC^A 1957 203
24 S 432 ALLE 1351 220
10 S 433 ATCO^H 723 491
16 S 434 BHP 1260 352
35 S 435 AU 1996 776
9 B 436 BCS 1615 340
21 B 437 ATTO 1625 745
25 S 438 BGH 1610 35
35 B 439 BAC^O 1335 436
30 S 440 AGO 1106 555
32 B 441 BKE 395 325
19 S 442 AHH 1365 976
2 B 443 AAC 1516 536
34 B 444 BGSX 1319 497
1 B 445 AIR 1937 230
24 B 446 BK 975 728
36 S 447 BAM 359 809
3 S 448 ACR 1883 510
25 B 449 BMA 1323 564
28 B 450 AMH^G 239 329
26 B 451 BCC 1824 380
12 S 452 AMRC 713 683
36 S 453 AUD 1031 47
19 S 454 BERY 1567 474
28 B 455 AEE 588 766
23 S 456 BMI 1249 13
33 B 457 AZEK 478 599
8 S 458 AZRE 1926 834
39 S 459 BAC^K 1746 976
7 B 460 AUB^A 1942 965
14 S 461 ASR 1252 795
17 B 462 BGT 1852 915
11 B 463 APGB 1770 634
15 B 464 AHT^D 574 276
19 B 465 BDXB 994 305
